Workbook

Sheet ReadMe
A1: MIL-STD-882E w/Change 1 — System Safety Basis of Estimate (BOE) Model
A3: How it works
A4: 1. Inputs: enter program start/end, the two SAR anchor estimates (P50 and P90 hours), the complexity level, the SwCI level, and the quantity drivers (subsystems, test events, ECPs, reviews).
A5: 2. Milestones: define your program milestones as months-after-start (or type a hard date in the override column). Every task's dates hang off these milestones.
A6: 3. BOE: one row per 882E task (and per LOE item). Each row is anchored one of three ways:
A7: SAR = ratio × SAR P50 hours × quantity (documents and analyses — the default)
A8: LOE = hours per month × months between its start and end milestones × quantity (meetings, HTS upkeep, reporting)
A9: FIXED = hours entered directly × quantity (anything you want to hard-size)
A10: The result is multiplied by the complexity factor (if 'Apply Cx' = Y) and the SwCI multiplier (if 'Apply SwCI' = Y).
A11: P90 = P50 × (SAR P90 ÷ SAR P50) unless a per-row P90 ratio override is entered.
A12: Set 'Tasked' to N to remove a task from the estimate without deleting the row (only Sections 3 and 4 of the standard are mandatory; tasks are cited by contract).
A13: 4. Phasing: spreads each row's hours evenly across its start–end window by month, and shows the monthly FTE load. Switch P50/P90 on the Inputs sheet.
... A31: Milestones: up to 30 rows are pre-wired. BOE: insert a row inside the table and copy the formulas down from the row above; Phasing and Timeline reference BOE rows 6–60.

Sheet Summary
A1: Estimate Summary
A2: ="Complexity: "&Inputs!$B$13&" ("&TEXT(Inputs!$B$16,"0.00")&") | SwCI "&Inputs!$B$21&" (×"&TEXT(Inputs!$B$22,"0.00")&") | SAR P50 "&TEXT(Inputs!$B$9,"#,##0")&" h, P90 "&TEXT(Inputs!$B$10,"#,##0")&" h" -> Complexity: Moderate (1.00) | SwCI 2 (×1.30) | SAR P50 800 h, P90 1,200 h
A4: Section | B4: Rows tasked | C4: P50 hours | D4: P90 hours | E4: P50 share | F4: P90 ÷ P50
A5: 100 Management | B5: =COUNTIFS(BOE!$B$6:$B$60,A5,BOE!$E$6:$E$60,"Y") -> 8 | C5: =SUMIFS(BOE!$R$6:$R$60,BOE!$B$6:$B$60,A5) -> 2434.924 | D5: =SUMIFS(BOE!$T$6:$T$60,BOE!$B$6:$B$60,A5) -> 3652.386 | E5: =IF($C$10>0,C5/$C$10,0) -> 0.2037048 | F5: =IF(C5>0,D5/C5,0) -> 1.5
A6: 200 Analysis | B6: =COUNTIFS(BOE!$B$6:$B$60,A6,BOE!$E$6:$E$60,"Y") -> 9 | C6: =SUMIFS(BOE!$R$6:$R$60,BOE!$B$6:$B$60,A6) -> 5424 | D6: =SUMIFS(BOE!$T$6:$T$60,BOE!$B$6:$B$60,A6) -> 8136 | E6: =IF($C$10>0,C6/$C$10,0) -> 0.45376973 | F6: =IF(C6>0,D6/C6,0) -> 1.5
A7: 300 Evaluation | B7: =COUNTIFS(BOE!$B$6:$B$60,A7,BOE!$E$6:$E$60,"Y") -> 3 | C7: =SUMIFS(BOE!$R$6:$R$60,BOE!$B$6:$B$60,A7) -> 1920 | D7: =SUMIFS(BOE!$T$6:$T$60,BOE!$B$6:$B$60,A7) -> 2880 | E7: =IF($C$10>0,C7/$C$10,0) -> 0.16062645 | F7: =IF(C7>0,D7/C7,0) -> 1.5
A8: 400 Verification | B8: =COUNTIFS(BOE!$B$6:$B$60,A8,BOE!$E$6:$E$60,"Y") -> 2 | C8: =SUMIFS(BOE!$R$6:$R$60,BOE!$B$6:$B$60,A8) -> 1352 | D8: =SUMIFS(BOE!$T$6:$T$60,BOE!$B$6:$B$60,A8) -> 2028 | E8: =IF($C$10>0,C8/$C$10,0) -> 0.11310779 | F8: =IF(C8>0,D8/C8,0) -> 1.5
A9: LOE / Other | B9: =COUNTIFS(BOE!$B$6:$B$60,A9,BOE!$E$6:$E$60,"Y") -> 3 | C9: =SUMIFS(BOE!$R$6:$R$60,BOE!$B$6:$B$60,A9) -> 822.27515 | D9: =SUMIFS(BOE!$T$6:$T$60,BOE!$B$6:$B$60,A9) -> 1233.4127 | E9: =IF($C$10>0,C9/$C$10,0) -> 0.06879122 | F9: =IF(C9>0,D9/C9,0) -> 1.5
A10: TOTAL | B10: =SUM(B5:B9) -> 25 | C10: =SUM(C5:C9) -> 11953.199 | D10: =SUM(D5:D9) -> 17929.799 | E10: =SUM(E5:E9) -> 1 | F10: =IF(C10>0,D10/C10,0) -> 1.5
A12: Program metrics
A13: Program duration (months) | B13: =(Inputs!$B$5-Inputs!$B$4)/(365.25/12) -> 35.876797
A14: Average FTE — P50 | B14: =IF(B13>0,C10/(B13*Inputs!$B$6),0) -> 2.1357278
A15: Average FTE — P90 | B15: =IF(B13>0,D10/(B13*Inputs!$B$6),0) -> 3.2035917
A16: Peak monthly FTE (phasing basis) | B16: =MAX(Phasing!F62:BY62) -> 4.130449
A17: Peak month hours (phasing basis) | B17: =MAX(Phasing!F61:BY61) -> 644.35005
A18: Phasing basis in use | B18: =Inputs!$B$7 -> P50
A19: Hours per FTE-month | B19: =Inputs!$B$6 -> 156
A21: Anchor-ratio check: SAR-anchored rows as a multiple of one SAR (P50, before factors)
A22: Sum of SAR ratios × qty (tasked rows) | B22: =SUMPRODUCT((BOE!$F$6:$F$60="SAR")*(BOE!$E$6:$E$60="Y")*(BOE!$G$6:$G$60)*(BOE!$H$6:$H$60)) -> 10.9 | C22: e.g. 9.5 means the SAR-anchored documents total ~9.5 SARs of effort. Useful sanity check against your historical program totals.
A24: Staffing plan (from Staffing sheet)
A25: Peak headcount in plan (FTE) | B25: =Staffing!B35 -> 4.5
A26: Average headcount (FTE) | B26: =Staffing!B36 -> 2.3888889
A27: Total staff-months | B27: =Staffing!B37 -> 86
A28: Overall utilization | B28: =Staffing!B40 -> 0.89096595

Sheet Inputs
A1: Program Inputs & Assumptions
A2: Blue cells on yellow are inputs. Everything else in the workbook derives from this sheet and Milestones.
A4: Program start date | B4: 46391 | F4: Month 1 of the timeline. Milestones are offsets from this date.
A5: Program end date | B5: 47483 | F5: Timeline and phasing stop here (max 72 months).
A6: Hours per FTE-month | B6: 156 | F6: Used to convert monthly hours to FTE loading. 1,872 hrs/yr ÷ 12.
A7: Phasing basis (P50 / P90) | B7: P50 | F7: Which estimate the Phasing and Timeline sheets spread by month.
A8: SAR anchor (Task 301 Safety Assessment Report)
A9: SAR P50 hours | B9: 800 | F9: User estimate: hours to produce the SAR at a 50% confidence level. All SAR-anchored rows scale from this.
A10: SAR P90 hours | B10: 1200 | F10: User estimate: hours at 90% confidence. The P90/P50 ratio drives every other row's P90 unless overridden.
A11: P90 / P50 ratio | B11: =IF(B9>0,B10/B9,1) -> 1.5 | F11: Derived. Applied to all rows without a per-row override.
A12: Complexity
A13: Program complexity level | B13: Moderate | D13: Level | E13: Factor | F13: Pick from the table at right.
A14: Complexity factor (lookup) | B14: =IFERROR(INDEX($E$14:$E$17,MATCH($B$13,$D$14:$D$17,0)),1) -> 1 | D14: Low | E14: 0.8
A15: Complexity factor override (optional) | D15: Moderate | E15: 1 | F15: Leave blank to use the lookup. Enter e.g. 1.25 to override.
A16: Effective complexity factor | B16: =IF(B15<>"",B15,B14) -> 1 | D16: High | E16: 1.3 | F16: Multiplies every BOE row flagged 'Apply Cx = Y'.
D17: Very High | E17: 1.6
D18: Complexity guide: Low = mature design, few interfaces, no safety-significant software. Moderate = typical. High = new design, many subsystems/interfaces, safety-significant software. Very High = autonomous/novel energy storage, SoS interfaces, multiple risk-acceptance authorities.
A20: Software criticality (Section 4.4)
A21: Software Criticality Index (SwCI 1–5) | B21: 2 | D21: SwCI | E21: Multiplier | F21: From Table V: severity × software control category. BMS firmware that alone opens contactors on a Catastrophic hazard = SwCI 1; with an independent HW protection layer = SwCI 2–3.
A22: SwCI multiplier (lookup) | B22: =IFERROR(INDEX($E$22:$E$26,MATCH($B$21,$D$22:$D$26,0)),1) -> 1.3 | D22: 1 | E22: 1.5 | F22: Multiplies rows flagged 'Apply SwCI = Y' (software-touching analyses, verification, LOR).
D23: 2 | E23: 1.3
D24: 3 | E24: 1.15
D25: 4 | E25: 1
D26: 5 | E26: 0.8
D27: Multiplier rationale: SwCI 1 adds code-level analysis and in-depth safety testing (Table V); SwCI 5 means no safety-specific software analysis.
A29: Quantity drivers
A30: Number of subsystems analyzed (Task 204) | B30: 6 | F30: e.g., pack/modules, BMS, contactor/precharge, HV distribution, thermal mgmt, charger interface.
A31: Number of test events (Task 303) | B31: 8 | F31: Each needs hazard review, Safety Release support, post-test analysis.
A32: Expected ECPs / change notices reviewed (Task 304) | B32: 20 | F32: Over the program life.
A33: Government reviews / audits / boards supported (Task 104) | B33: 6 | F33: SRR, PDR, CDR, TRR, safety boards, audits.
A34: Design reviews with safety packages (SRR/PDR/CDR/TRR) | B34: 4 | F34: Safety data package preparation per review.
A36: Labor categories (used on BOE column V and the Staffing sheet)
A37: Role | B37: Typical content
A38: Safety Lead | B38: SSPP, SAR, reviews, boards, SSWG, reporting
A39: System Safety Engineer | B39: PHA, SRHA, SSHA, SHA, O&SHA, HHA, EHA, verification, ECP reviews
A40: Software Safety Engineer | B40: FHA, software causal analysis, LOR tasks, SwCI evidence
A41: Safety Analyst | B41: HTS setup and upkeep, data packages, document production
A43: Staffing-plan parameters (Staffing sheet)
A44: Smoothing window (months: 1, 3 or 5) | B44: 3 | F44: Centered moving average applied to raw FTE demand before rounding to headcount.
A45: Headcount granularity (FTE) | B45: 0.5 | F45: Round smoothed demand up to this step (0.5 = half-time people allowed; 1 = whole people only).
...

Sheet Milestones
A1: Program Milestones
A2: Enter each milestone as months after program start (column C), or type a hard date in column D to override. Column E is what the BOE uses. Keep names unique — the BOE picks them from a dropdown.
A4: # | B4: Milestone | C4: Months after start | D4: Date override (optional) | E4: Milestone date (used) | F4: Description
A5: 1 | B5: Program Start | C5: 0 | E5: =IF(B5="","",IF(D5<>"",D5,IF(C5<>"",EDATE(Inputs!$B$4,C5),""))) -> 46391 | F5: Contract award / program kickoff.
A6: 2 | B6: SRR | C6: 3 | E6: =IF(B6="","",IF(D6<>"",D6,IF(C6<>"",EDATE(Inputs!$B$4,C6),""))) -> 46481 | F6: System Requirements Review.
A7: 3 | B7: SFR | C7: 6 | E7: =IF(B7="","",IF(D7<>"",D7,IF(C7<>"",EDATE(Inputs!$B$4,C7),""))) -> 46572 | F7: System Functional Review.
A8: 4 | B8: PDR | C8: 10 | E8: =IF(B8="","",IF(D8<>"",D8,IF(C8<>"",EDATE(Inputs!$B$4,C8),""))) -> 46695 | F8: Preliminary Design Review.
A9: 5 | B9: CDR | C9: 16 | E9: =IF(B9="","",IF(D9<>"",D9,IF(C9<>"",EDATE(Inputs!$B$4,C9),""))) -> 46877 | F9: Critical Design Review.
A10: 6 | B10: TRR | C10: 24 | E10: =IF(B10="","",IF(D10<>"",D10,IF(C10<>"",EDATE(Inputs!$B$4,C10),""))) -> 47122 | F10: Test Readiness Review.
A11: 7 | B11: Test Start | C11: 25 | E11: =IF(B11="","",IF(D11<>"",D11,IF(C11<>"",EDATE(Inputs!$B$4,C11),""))) -> 47153 | F11: First safety-relevant test event (bench / HIL / pack abuse).
A12: 8 | B12: Test Complete | C12: 31 | E12: =IF(B12="","",IF(D12<>"",D12,IF(C12<>"",EDATE(Inputs!$B$4,C12),""))) -> 47334 | F12: Last test event complete.
A13: 9 | B13: SAR Submittal | C13: 33 | E13: =IF(B13="","",IF(D13<>"",D13,IF(C13<>"",EDATE(Inputs!$B$4,C13),""))) -> 47395 | F13: Safety Assessment Report delivered for risk acceptance.
A14: 10 | B14: Program End | D14: =Inputs!$B$5 -> 47483 | E14: =IF(B14="","",IF(D14<>"",D14,IF(C14<>"",EDATE(Inputs!$B$4,C14),""))) -> 47483 | F14: Contract end — taken from Inputs.
A15: 11 | E15: =IF(B15="","",IF(D15<>"",D15,IF(C15<>"",EDATE(Inputs!$B$4,C15),"")))
A16: 12 | E16: =IF(B16="","",IF(D16<>"",D16,IF(C16<>"",EDATE(Inputs!$B$4,C16),"")))
A17: 13 | E17: =IF(B17="","",IF(D17<>"",D17,IF(C17<>"",EDATE(Inputs!$B$4,C17),"")))
A18: 14 | E18: =IF(B18="","",IF(D18<>"",D18,IF(C18<>"",EDATE(Inputs!$B$4,C18),"")))
A19: 15 | E19: =IF(B19="","",IF(D19<>"",D19,IF(C19<>"",EDATE(Inputs!$B$4,C19),"")))
A20: 16 | E20: =IF(B20="","",IF(D20<>"",D20,IF(C20<>"",EDATE(Inputs!$B$4,C20),"")))
A21: 17 | E21: =IF(B21="","",IF(D21<>"",D21,IF(C21<>"",EDATE(Inputs!$B$4,C21),"")))
A22: 18 | E22: =IF(B22="","",IF(D22<>"",D22,IF(C22<>"",EDATE(Inputs!$B$4,C22),"")))
A23: 19 | E23: =IF(B23="","",IF(D23<>"",D23,IF(C23<>"",EDATE(Inputs!$B$4,C23),"")))
A24: 20 | E24: =IF(B24="","",IF(D24<>"",D24,IF(C24<>"",EDATE(Inputs!$B$4,C24),"")))
A25: 21 | E25: =IF(B25="","",IF(D25<>"",D25,IF(C25<>"",EDATE(Inputs!$B$4,C25),"")))
A26: 22 | E26: =IF(B26="","",IF(D26<>"",D26,IF(C26<>"",EDATE(Inputs!$B$4,C26),"")))
... A34: 30 | E34: =IF(B34="","",IF(D34<>"",D34,IF(C34<>"",EDATE(Inputs!$B$4,C34),"")))

Sheet BOE
A1: Basis of Estimate — MIL-STD-882E w/Change 1 Tasks
A2: Anchor: SAR = ratio × SAR P50 × Qty | LOE = hrs/month × months in window × Qty | FIXED = hours × Qty. Then × complexity (if Apply Cx=Y) × SwCI multiplier (if Apply SwCI=Y). P90 = P50 × P90/P50 ratio (or row override).
A3: SAR P50 anchor: | B3: =Inputs!$B$9 -> 800 | C3: Cx factor: | D3: =Inputs!$B$16 -> 1 | E3: SwCI mult: | F3: =Inputs!$B$22 -> 1.3 | G3: P90/P50: | H3: =Inputs!$B$11 -> 1.5
A5: Task | B5: Section | C5: Title / Work Element | D5: Deliverable | E5: Tasked (Y/N) | F5: Anchor type | G5: Driver value (ratio of SAR | hrs/month | hours) | H5: Qty | I5: Apply Cx (Y/N) | J5: Apply SwCI (Y/N) | K5: Start milestone | L5: Start offset (wks) | M5: End milestone | N5: End offset (wks) | O5: Start date | P5: End date | Q5: Months | R5: P50 hours | S5: P90 ratio override | T5: P90 hours | U5: Basis / assumption | V5: Labor category
A6: 101 | B6: 100 Management | C6: Hazard identification & mitigation effort using the system safety methodology (program execution) | D6: Program execution | E6: Y | F6: LOE | G6: 20 | H6: 1 | I6: Y | J6: N | K6: Program Start | L6: 0 | M6: Program End | N6: 0 | O6: =IFERROR(INDEX(Milestones!$E$5:$E$34,MATCH($K6,Milestones!$B$5:$B$34,0))+N($L6)*7,"") -> 46391 | P6: =IFERROR(INDEX(Milestones!$E$5:$E$34,MATCH($M6,Milestones!$B$5:$B$34,0))+N($N6)*7,"") -> 47483 | Q6: =IF(OR($O6="",$P6=""),"",MAX(0,($P6-$O6)/(365.25/12))) -> 35.876797 | R6: =IF(OR($A6="",$E6<>"Y"),0,IF($F6="SAR",$G6*Inputs!$B$9,IF($F6="LOE",$G6*N($Q6),$G6))*N($H6)*IF($I6="Y",Inputs!$B$16,1)*IF($J6="Y",Inputs!$B$22,1)) -> 717.53593 | T6: =$R6*IF($S6<>"",$S6,Inputs!$B$11) -> 1076.3039 | U6: Ongoing management of the safety effort: planning, roles, subcontractor flow-down, status reporting, IMS inputs (101.2.1–101.2.9). Sized as a monthly run-rate. | V6: Safety Lead
A7: 102 | B7: 100 Management | C7: System Safety Program Plan (SSPP) | D7: SSPP | E7: Y | F7: SAR | G7: 0.4 | H7: 1 | I7: Y | J7: N | K7: Program Start | L7: 0 | M7: SRR | N7: 0 | O7: =IFERROR(INDEX(Milestones!$E$5:$E$34,MATCH($K7,Milestones!$B$5:$B$34,0))+N($L7)*7,"") -> 46391 | P7: =IFERROR(INDEX(Milestones!$E$5:$E$34,MATCH($M7,Milestones!$B$5:$B$34,0))+N($N7)*7,"") -> 46481 | Q7: =IF(OR($O7="",$P7=""),"",MAX(0,($P7-$O7)/(365.25/12))) -> 2.9568789 | R7: =IF(OR($A7="",$E7<>"Y"),0,IF($F7="SAR",$G7*Inputs!$B$9,IF($F7="LOE",$G7*N($Q7),$G7))*N($H7)*IF($I7="Y",Inputs!$B$16,1)*IF($J7="Y",Inputs!$B$22,1)) -> 320 | T7: =$R7*IF($S7<>"",$S7,Inputs!$B$11) -> 480 | U7: Plan covering scope, interfaces, organization, milestones, requirements, analyses, V&V, audits, training, incident reporting (102.2.1–102.2.11). ~40% of a SAR. | V7: Safety Lead
A8: 103 | B8: 100 Management | C8: Hazard Management Plan (HMP) — other functional disciplines | D8: HMP | E8: N | F8: SAR | G8: 0.3 | H8: 1 | I8: Y | J8: N | K8: Program Start | L8: 0 | M8: SRR | N8: 0 | O8: =IFERROR(INDEX(Milestones!$E$5:$E$34,MATCH($K8,Milestones!$B$5:$B$34,0))+N($L8)*7,"") -> 46391 | P8: =IFERROR(INDEX(Milestones!$E$5:$E$34,MATCH($M8,Milestones!$B$5:$B$34,0))+N($N8)*7,"") -> 46481 | Q8: =IF(OR($O8="",$P8=""),"",MAX(0,($P8-$O8)/(365.25/12))) -> 2.9568789 | R8: =IF(OR($A8="",$E8<>"Y"),0,IF($F8="SAR",$G8*Inputs!$B$9,IF($F8="LOE",$G8*N($Q8),$G8))*N($H8)*IF($I8="Y",Inputs!$B$16,1)*IF($J8="Y",Inputs!$B$22,1)) -> 0 | T8: =$R8*IF($S8<>"",$S8,Inputs!$B$11) -> 0 | U8: Equivalent of the SSPP for a non-system-safety discipline (103). Default Not Tasked; turn on if a separate discipline plan is contracted. | V8: Safety Lead
A9: 104 | B9: 100 Management | C9: Support of Government reviews / audits / boards | D9: Review support | E9: Y | F9: SAR | G9: 0.05 | H9: =Inputs!$B$33 -> 6 | I9: Y | J9: N | K9: SRR | L9: -4 | M9: Program End | N9: 0 | O9: =IFERROR(INDEX(Milestones!$E$5:$E$34,MATCH($K9,Milestones!$B$5:$B$34,0))+N($L9)*7,"") -> 46453 | P9: =IFERROR(INDEX(Milestones!$E$5:$E$34,MATCH($M9,Milestones!$B$5:$B$34,0))+N($N9)*7,"") -> 47483 | Q9: =IF(OR($O9="",$P9=""),"",MAX(0,($P9-$O9)/(365.25/12))) -> 33.839836 | R9: =IF(OR($A9="",$E9<>"Y"),0,IF($F9="SAR",$G9*Inputs!$B$9,IF($F9="LOE",$G9*N($Q9),$G9))*N($H9)*IF($I9="Y",Inputs!$B$16,1)*IF($J9="Y",Inputs!$B$22,1)) -> 240 | T9: =$R9*IF($S9<>"",$S9,Inputs!$B$11) -> 360 | U9: Per review/audit/board (104.2.1): prep, attendance, action closure. ~5% of a SAR each × number of reviews (Inputs). | V9: Safety Lead
A10: 105 | B10: 100 Management | C10: Integrated Product Team / Working Group support | D10: IPT / SSWG participation | E10: Y | F10: LOE | G10: 12 | H10: 1 | I10: Y | J10: N | K10: Program Start | L10: 0 | M10: Program End | N10: 0 | O10: =IFERROR(INDEX(Milestones!$E$5:$E$34,MATCH($K10,Milestones!$B$5:$B$34,0))+N($L10)*7,"") -> 46391 | P10: =IFERROR(INDEX(Milestones!$E$5:$E$34,MATCH($M10,Milestones!$B$5:$B$34,0))+N($N10)*7,"") -> 47483 | Q10: =IF(OR($O10="",$P10=""),"",MAX(0,($P10-$O10)/(365.25/12))) -> 35.876797 | R10: =IF(OR($A10="",$E10<>"Y"),0,IF($F10="SAR",$G10*Inputs!$B$9,IF($F10="LOE",$G10*N($Q10),$G10))*N($H10)*IF($I10="Y",Inputs!$B$16,1)*IF($J10="Y",Inputs!$B$22,1)) -> 430.52156 | T10: =$R10*IF($S10<>"",$S10,Inputs!$B$11) -> 645.78234 | U10: Standing membership in designated IPTs and the System Safety Working Group (105.2). Monthly run-rate; raise if several IPTs are supported. | V10: Safety Lead
A11: 106a | B11: 100 Management | C11: Hazard Tracking System — establish | D11: HTS (initial) | E11: Y | F11: SAR | G11: 0.15 | H11: 1 | I11: Y | J11: N | K11: Program Start | L11: 0 | M11: SRR | N11: 0 | O11: =IFERROR(INDEX(Milestones!$E$5:$E$34,MATCH($K11,Milestones!$B$5:$B$34,0))+N($L11)*7,"") -> 46391 | P11: =IFERROR(INDEX(Milestones!$E$5:$E$34,MATCH($M11,Milestones!$B$5:$B$34,0))+N($N11)*7,"") -> 46481 | Q11: =IF(OR($O11="",$P11=""),"",MAX(0,($P11-$O11)/(365.25/12))) -> 2.9568789 | R11: =IF(OR($A11="",$E11<>"Y"),0,IF($F11="SAR",$G11*Inputs!$B$9,IF($F11="LOE",$G11*N($Q11),$G11))*N($H11)*IF($I11="Y",Inputs!$B$16,1)*IF($J11="Y",Inputs!$B$22,1)) -> 120 | T11: =$R11*IF($S11<>"",$S11,Inputs!$B$11) -> 180 | U11: Stand up the closed-loop HTS with the required data elements (106.2) and Government access controls (106.2.1). | V11: Safety Analyst
A12: 106b | B12: 100 Management | C12: Hazard Tracking System — maintain | D12: HTS (upkeep) | E12: Y | F12: LOE | G12: 8 | H12: 1 | I12: Y | J12: N | K12: SRR | L12: 0 | M12: Program End | N12: 0 | O12: =IFERROR(INDEX(Milestones!$E$5:$E$34,MATCH($K12,Milestones!$B$5:$B$34,0))+N($L12)*7,"") -> 46481 | P12: =IFERROR(INDEX(Milestones!$E$5:$E$34,MATCH($M12,Milestones!$B$5:$B$34,0))+N($N12)*7,"") -> 47483 | Q12: =IF(OR($O12="",$P12=""),"",MAX(0,($P12-$O12)/(365.25/12))) -> 32.919918 | R12: =IF(OR($A12="",$E12<>"Y"),0,IF($F12="SAR",$G12*Inputs!$B$9,IF($F12="LOE",$G12*N($Q12),$G12))*N($H12)*IF($I12="Y",Inputs!$B$16,1)*IF($J12="Y",Inputs!$B$22,1)) -> 263.35934 | T12: =$R12*IF($S12<>"",$S12,Inputs!$B$11) -> 395.03901 | U12: Keep hazard records, risk assessments, mitigation status and acceptance current through the life-cycle (106.2, 4.3.8). | V12: Safety Analyst
A13: 107 | B13: 100 Management | C13: Hazard Management Progress Report | D13: Periodic progress reports | E13: Y | F13: LOE | G13: 4 | H13: 1 | I13: Y | J13: N | K13: Program Start | L13: 0 | M13: Program End | N13: 0 | O13: =IFERROR(INDEX(Milestones!$E$5:$E$34,MATCH($K13,Milestones!$B$5:$B$34,0))+N($L13)*7,"") -> 46391 | P13: =IFERROR(INDEX(Milestones!$E$5:$E$34,MATCH($M13,Milestones!$B$5:$B$34,0))+N($N13)*7,"") -> 47483 | Q13: =IF(OR($O13="",$P13=""),"",MAX(0,($P13-$O13)/(365.25/12))) -> 35.876797 | R13: =IF(OR($A13="",$E13<>"Y"),0,IF($F13="SAR",$G13*Inputs!$B$9,IF($F13="LOE",$G13*N($Q13),$G13))*N($H13)*IF($I13="Y",Inputs!$B$16,1)*IF($J13="Y",Inputs!$B$22,1)) -> 143.50719 | T13: =$R13*IF($S13<>"",$S13,Inputs!$B$11) -> 215.26078 | U13: Periodic report summarizing hazard status, risk assessments, mitigations and open actions (107.2). Assumes monthly. | V13: Safety Lead
A14: 108 | B14: 100 Management | C14: Hazardous Materials Management Plan (HMMP) | D14: HMMP + HAZMAT list | E14: Y | F14: SAR | G14: 0.25 | H14: 1 | I14: Y | J14: N | K14: Program Start | L14: 0 | M14: PDR | N14: 0 | O14: =IFERROR(INDEX(Milestones!$E$5:$E$34,MATCH($K14,Milestones!$B$5:$B$34,0))+N($L14)*7,"") -> 46391 | P14: =IFERROR(INDEX(Milestones!$E$5:$E$34,MATCH($M14,Milestones!$B$5:$B$34,0))+N($N14)*7,"") -> 46695 | Q14: =IF(OR($O14="",$P14=""),"",MAX(0,($P14-$O14)/(365.25/12))) -> 9.9876797 | R14: =IF(OR($A14="",$E14<>"Y"),0,IF($F14="SAR",$G14*Inputs!$B$9,IF($F14="LOE",$G14*N($Q14),$G14))*N($H14)*IF($I14="Y",Inputs!$B$16,1)*IF($J14="Y",Inputs!$B$22,1)) -> 200 | T14: =$R14*IF($S14<>"",$S14,Inputs!$B$11) -> 300 | U14: HAZMAT identification, categorization, tracking (108.2.1–108.2.4). Relevant to Li-ion cells, electrolyte, coolant. | V14: System Safety Engineer
A15: 201 | B15: 200 Analysis | C15: Preliminary Hazard List (PHL) | D15: PHL | E15: Y | F15: SAR | G15: 0.2 | H15: 1 | I15: Y | J15: N | K15: Program Start | L15: 0 | M15: SRR | N15: 0 | O15: =IFERROR(INDEX(Milestones!$E$5:$E$34,MATCH($K15,Milestones!$B$5:$B$34,0))+N($L15)*7,"") -> 46391 | P15: =IFERROR(INDEX(Milestones!$E$5:$E$34,MATCH($M15,Milestones!$B$5:$B$34,0))+N($N15)*7,"") -> 46481 | Q15: =IF(OR($O15="",$P15=""),"",MAX(0,($P15-$O15)/(365.25/12))) -> 2.9568789 | R15: =IF(OR($A15="",$E15<>"Y"),0,IF($F15="SAR",$G15*Inputs!$B$9,IF($F15="LOE",$G15*N($Q15),$G15))*N($H15)*IF($I15="Y",Inputs!$B$16,1)*IF($J15="Y",Inputs!$B$22,1)) -> 160 | T15: =$R15*IF($S15<>"",$S15,Inputs!$B$11) -> 240 | U15: Early hazard list from legacy/similar-system data and lessons learned (201.2.1–201.2.3). | V15: System Safety Engineer
A16: 202 | B16: 200 Analysis | C16: Preliminary Hazard Analysis (PHA) | D16: PHA report | E16: Y | F16: SAR | G16: 0.6 | H16: 1 | I16: Y | J16: N | K16: SRR | L16: 0 | M16: SFR | N16: 4 | O16: =IFERROR(INDEX(Milestones!$E$5:$E$34,MATCH($K16,Milestones!$B$5:$B$34,0))+N($L16)*7,"") -> 46481 | P16: =IFERROR(INDEX(Milestones!$E$5:$E$34,MATCH($M16,Milestones!$B$5:$B$34,0))+N($N16)*7,"") -> 46600 | Q16: =IF(OR($O16="",$P16=""),"",MAX(0,($P16-$O16)/(365.25/12))) -> 3.9096509 | R16: =IF(OR($A16="",$E16<>"Y"),0,IF($F16="SAR",$G16*Inputs!$B$9,IF($F16="LOE",$G16*N($Q16),$G16))*N($H16)*IF($I16="Y",Inputs!$B$16,1)*IF($J16="Y",Inputs!$B$22,1)) -> 480 | T16: =$R16*IF($S16<>"",$S16,Inputs!$B$11) -> 720 | U16: Initial risk assessment per hazard across the 202.2.2 hazard sources (energy, software, HAZMAT, environment, human factors, etc.). | V16: System Safety Engineer
A17: 203 | B17: 200 Analysis | C17: System Requirements Hazard Analysis (SRHA) | D17: SRHA + requirements traceability | E17: Y | F17: SAR | G17: 0.5 | H17: 1 | I17: Y | J17: Y | K17: SRR | L17: 0 | M17: CDR | N17: 0 | O17: =IFERROR(INDEX(Milestones!$E$5:$E$34,MATCH($K17,Milestones!$B$5:$B$34,0))+N($L17)*7,"") -> 46481 | P17: =IFERROR(INDEX(Milestones!$E$5:$E$34,MATCH($M17,Milestones!$B$5:$B$34,0))+N($N17)*7,"") -> 46877 | Q17: =IF(OR($O17="",$P17=""),"",MAX(0,($P17-$O17)/(365.25/12))) -> 13.010267 | R17: =IF(OR($A17="",$E17<>"Y"),0,IF($F17="SAR",$G17*Inputs!$B$9,IF($F17="LOE",$G17*N($Q17),$G17))*N($H17)*IF($I17="Y",Inputs!$B$16,1)*IF($J17="Y",Inputs!$B$22,1)) -> 520 | T17: =$R17*IF($S17<>"",$S17,Inputs!$B$11) -> 780 | U17: Derive safety design requirements, incorporate into specs, assess compliance through design (203.2.1–203.2.3). Continues through CDR. | V17: System Safety Engineer
A18: 204 | B18: 200 Analysis | C18: Subsystem Hazard Analysis (SSHA) | D18: SSHA report(s) | E18: Y | F18: SAR | G18: 0.3 | H18: =Inputs!$B$30 -> 6 | I18: Y | J18: Y | K18: PDR | L18: 0 | M18: CDR | N18: 4 | O18: =IFERROR(INDEX(Milestones!$E$5:$E$34,MATCH($K18,Milestones!$B$5:$B$34,0))+N($L18)*7,"") -> 46695 | P18: =IFERROR(INDEX(Milestones!$E$5:$E$34,MATCH($M18,Milestones!$B$5:$B$34,0))+N($N18)*7,"") -> 46905 | Q18: =IF(OR($O18="",$P18=""),"",MAX(0,($P18-$O18)/(365.25/12))) -> 6.899384 | R18: =IF(OR($A18="",$E18<>"Y"),0,IF($F18="SAR",$G18*Inputs!$B$9,IF($F18="LOE",$G18*N($Q18),$G18))*N($H18)*IF($I18="Y",Inputs!$B$16,1)*IF($J18="Y",Inputs!$B$22,1)) -> 1872 | T18: =$R18*IF($S18<>"",$S18,Inputs!$B$11) -> 2808 | U18: Per subsystem (Inputs qty): component failure modes, software causal factors, human error (204.2.1). ~30% of a SAR per subsystem. | V18: System Safety Engineer
A19: 205 | B19: 200 Analysis | C19: System Hazard Analysis (SHA) | D19: SHA report | E19: Y | F19: SAR | G19: 0.8 | H19: 1 | I19: Y | J19: Y | K19: PDR | L19: 0 | M19: CDR | N19: 8 | O19: =IFERROR(INDEX(Milestones!$E$5:$E$34,MATCH($K19,Milestones!$B$5:$B$34,0))+N($L19)*7,"") -> 46695 | P19: =IFERROR(INDEX(Milestones!$E$5:$E$34,MATCH($M19,Milestones!$B$5:$B$34,0))+N($N19)*7,"") -> 46933 | Q19: =IF(OR($O19="",$P19=""),"",MAX(0,($P19-$O19)/(365.25/12))) -> 7.8193018 | R19: =IF(OR($A19="",$E19<>"Y"),0,IF($F19="SAR",$G19*Inputs!$B$9,IF($F19="LOE",$G19*N($Q19),$G19))*N($H19)*IF($I19="Y",Inputs!$B$16,1)*IF($J19="Y",Inputs!$B$22,1)) -> 832 | T19: =$R19*IF($S19<>"",$S19,Inputs!$B$11) -> 1248 | U19: Subsystem interface and interrelationship hazards, software and human interfaces (205.2.1); design-change evaluation (205.2.4). | V19: System Safety Engineer
A20: 206 | B20: 200 Analysis | C20: Operating & Support Hazard Analysis (O&SHA) | D20: O&SHA report | E20: Y | F20: SAR | G20: 0.6 | H20: 1 | I20: Y | J20: N | K20: CDR | L20: 0 | M20: TRR | N20: 0 | O20: =IFERROR(INDEX(Milestones!$E$5:$E$34,MATCH($K20,Milestones!$B$5:$B$34,0))+N($L20)*7,"") -> 46877 | P20: =IFERROR(INDEX(Milestones!$E$5:$E$34,MATCH($M20,Milestones!$B$5:$B$34,0))+N($N20)*7,"") -> 47122 | Q20: =IF(OR($O20="",$P20=""),"",MAX(0,($P20-$O20)/(365.25/12))) -> 8.0492813 | R20: =IF(OR($A20="",$E20<>"Y"),0,IF($F20="SAR",$G20*Inputs!$B$9,IF($F20="LOE",$G20*N($Q20),$G20))*N($H20)*IF($I20="Y",Inputs!$B$16,1)*IF($J20="Y",Inputs!$B$22,1)) -> 480 | T20: =$R20*IF($S20<>"",$S20,Inputs!$B$11) -> 720 | U20: Operations, maintenance, test, storage, transport, disposal hazards; procedures, warnings, PPE (206.2.1–206.2.5). | V20: System Safety Engineer
A21: 207 | B21: 200 Analysis | C21: Health Hazard Analysis (HHA) | D21: HHA report | E21: Y | F21: SAR | G21: 0.35 | H21: 1 | I21: Y | J21: N | K21: PDR | L21: 0 | M21: CDR | N21: 0 | O21: =IFERROR(INDEX(Milestones!$E$5:$E$34,MATCH($K21,Milestones!$B$5:$B$34,0))+N($L21)*7,"") -> 46695 | P21: =IFERROR(INDEX(Milestones!$E$5:$E$34,MATCH($M21,Milestones!$B$5:$B$34,0))+N($N21)*7,"") -> 46877 | Q21: =IF(OR($O21="",$P21=""),"",MAX(0,($P21-$O21)/(365.25/12))) -> 5.9794661 | R21: =IF(OR($A21="",$E21<>"Y"),0,IF($F21="SAR",$G21*Inputs!$B$9,IF($F21="LOE",$G21*N($Q21),$G21))*N($H21)*IF($I21="Y",Inputs!$B$16,1)*IF($J21="Y",Inputs!$B$22,1)) -> 280 | T21: =$R21*IF($S21<>"",$S21,Inputs!$B$11) -> 420 | U21: Chemical, electrical, thermal, noise and other health hazards per 207.2.2–207.2.3 categories (electrolyte, HF, HV). | V21: System Safety Engineer
A22: 208 | B22: 200 Analysis | C22: Functional Hazard Analysis (FHA) | D22: FHA + SCF/SCI list | E22: Y | F22: SAR | G22: 0.5 | H22: 1 | I22: Y | J22: Y | K22: SRR | L22: 0 | M22: PDR | N22: 0 | O22: =IFERROR(INDEX(Milestones!$E$5:$E$34,MATCH($K22,Milestones!$B$5:$B$34,0))+N($L22)*7,"") -> 46481 | P22: =IFERROR(INDEX(Milestones!$E$5:$E$34,MATCH($M22,Milestones!$B$5:$B$34,0))+N($N22)*7,"") -> 46695 | Q22: =IF(OR($O22="",$P22=""),"",MAX(0,($P22-$O22)/(365.25/12))) -> 7.0308008 | R22: =IF(OR($A22="",$E22<>"Y"),0,IF($F22="SAR",$G22*Inputs!$B$9,IF($F22="LOE",$G22*N($Q22),$G22))*N($H22)*IF($I22="Y",Inputs!$B$16,1)*IF($J22="Y",Inputs!$B$22,1)) -> 520 | T22: =$R22*IF($S22<>"",$S22,Inputs!$B$11) -> 780 | U22: Loss/degraded/out-of-sequence function hazards, identify SCFs/SCIs, map to HW/SW/human (208.2.1). Feeds the fault-injection list. | V22: Software Safety Engineer
A23: 209 | B23: 200 Analysis | C23: System-of-Systems Hazard Analysis | D23: SoS HA report | E23: N | F23: SAR | G23: 0.4 | H23: 1 | I23: Y | J23: N | K23: PDR | L23: 0 | M23: CDR | N23: 0 | O23: =IFERROR(INDEX(Milestones!$E$5:$E$34,MATCH($K23,Milestones!$B$5:$B$34,0))+N($L23)*7,"") -> 46695 | P23: =IFERROR(INDEX(Milestones!$E$5:$E$34,MATCH($M23,Milestones!$B$5:$B$34,0))+N($N23)*7,"") -> 46877 | Q23: =IF(OR($O23="",$P23=""),"",MAX(0,($P23-$O23)/(365.25/12))) -> 5.9794661 | R23: =IF(OR($A23="",$E23<>"Y"),0,IF($F23="SAR",$G23*Inputs!$B$9,IF($F23="LOE",$G23*N($Q23),$G23))*N($H23)*IF($I23="Y",Inputs!$B$16,1)*IF($J23="Y",Inputs!$B$22,1)) -> 0 | T23: =$R23*IF($S23<>"",$S23,Inputs!$B$11) -> 0 | U23: Unique SoS hazards and traceability (209.2.1–209.2.4). Default Not Tasked; enable if the vehicle integrates into a larger SoS. | V23: System Safety Engineer
A24: 210 | B24: 200 Analysis | C24: Environmental Hazard Analysis (EHA) | D24: EHA report | E24: Y | F24: SAR | G24: 0.35 | H24: 1 | I24: Y | J24: N | K24: PDR | L24: 0 | M24: CDR | N24: 0 | O24: =IFERROR(INDEX(Milestones!$E$5:$E$34,MATCH($K24,Milestones!$B$5:$B$34,0))+N($L24)*7,"") -> 46695 | P24: =IFERROR(INDEX(Milestones!$E$5:$E$34,MATCH($M24,Milestones!$B$5:$B$34,0))+N($N24)*7,"") -> 46877 | Q24: =IF(OR($O24="",$P24=""),"",MAX(0,($P24-$O24)/(365.25/12))) -> 5.9794661 | R24: =IF(OR($A24="",$E24<>"Y"),0,IF($F24="SAR",$G24*Inputs!$B$9,IF($F24="LOE",$G24*N($Q24),$G24))*N($H24)*IF($I24="Y",Inputs!$B$16,1)*IF($J24="Y",Inputs!$B$22,1)) -> 280 | T24: =$R24*IF($S24<>"",$S24,Inputs!$B$11) -> 420 | U24: Environmental impacts, HAZMAT and pollutant hazards across the life-cycle (210.2.2–210.2.5). | V24: System Safety Engineer
A25: 301 | B25: 300 Evaluation | C25: Safety Assessment Report (SAR) — ANCHOR | D25: SAR | E25: Y | F25: SAR | G25: 1 | H25: 1 | I25: Y | J25: N | K25: TRR | L25: 0 | M25: SAR Submittal | N25: 0 | O25: =IFERROR(INDEX(Milestones!$E$5:$E$34,MATCH($K25,Milestones!$B$5:$B$34,0))+N($L25)*7,"") -> 47122 | P25: =IFERROR(INDEX(Milestones!$E$5:$E$34,MATCH($M25,Milestones!$B$5:$B$34,0))+N($N25)*7,"") -> 47395 | Q25: =IF(OR($O25="",$P25=""),"",MAX(0,($P25-$O25)/(365.25/12))) -> 8.9691992 | R25: =IF(OR($A25="",$E25<>"Y"),0,IF($F25="SAR",$G25*Inputs!$B$9,IF($F25="LOE",$G25*N($Q25),$G25))*N($H25)*IF($I25="Y",Inputs!$B$16,1)*IF($J25="Y",Inputs!$B$22,1)) -> 800 | T25: =$R25*IF($S25<>"",$S25,Inputs!$B$11) -> 1200 | U25: The anchor estimate. Ratio 1.00 by definition; hours come straight from Inputs SAR P50/P90. Summarizes hazards, residual risk, and recommendations for risk acceptance (301.2). | V25: Safety Lead
A26: 302 | B26: 300 Evaluation | C26: Hazard Management Assessment Report (HMAR) | D26: HMAR | E26: N | F26: SAR | G26: 0.8 | H26: 1 | I26: Y | J26: N | K26: TRR | L26: 0 | M26: SAR Submittal | N26: 0 | O26: =IFERROR(INDEX(Milestones!$E$5:$E$34,MATCH($K26,Milestones!$B$5:$B$34,0))+N($L26)*7,"") -> 47122 | P26: =IFERROR(INDEX(Milestones!$E$5:$E$34,MATCH($M26,Milestones!$B$5:$B$34,0))+N($N26)*7,"") -> 47395 | Q26: =IF(OR($O26="",$P26=""),"",MAX(0,($P26-$O26)/(365.25/12))) -> 8.9691992 | R26: =IF(OR($A26="",$E26<>"Y"),0,IF($F26="SAR",$G26*Inputs!$B$9,IF($F26="LOE",$G26*N($Q26),$G26))*N($H26)*IF($I26="Y",Inputs!$B$16,1)*IF($J26="Y",Inputs!$B$22,1)) -> 0 | T26: =$R26*IF($S26<>"",$S26,Inputs!$B$11) -> 0 | U26: Equivalent of the SAR for another functional discipline (302). Default Not Tasked. | V26: Safety Lead
A27: 303 | B27: 300 Evaluation | C27: Test & Evaluation participation | D27: Safety Releases, post-test analyses, T&E repository | E27: Y | F27: SAR | G27: 0.1 | H27: =Inputs!$B$31 -> 8 | I27: Y | J27: N | K27: Test Start | L27: -8 | M27: Test Complete | N27: 4 | O27: =IFERROR(INDEX(Milestones!$E$5:$E$34,MATCH($K27,Milestones!$B$5:$B$34,0))+N($L27)*7,"") -> 47097 | P27: =IFERROR(INDEX(Milestones!$E$5:$E$34,MATCH($M27,Milestones!$B$5:$B$34,0))+N($N27)*7,"") -> 47362 | Q27: =IF(OR($O27="",$P27=""),"",MAX(0,($P27-$O27)/(365.25/12))) -> 8.7063655 | R27: =IF(OR($A27="",$E27<>"Y"),0,IF($F27="SAR",$G27*Inputs!$B$9,IF($F27="LOE",$G27*N($Q27),$G27))*N($H27)*IF($I27="Y",Inputs!$B$16,1)*IF($J27="Y",Inputs!$B$22,1)) -> 640 | T27: =$R27*IF($S27<>"",$S27,Inputs!$B$11) -> 960 | U27: Per test event (Inputs qty): hazard review of test setup/procedures, Safety Release, post-test analysis and HTS update (303.2.1–303.2.3). Your fault-injection campaign lives here. | V27: System Safety Engineer
A28: 304 | B28: 300 Evaluation | C28: Review of ECPs, change notices, deficiency reports, waivers | D28: Change reviews | E28: Y | F28: SAR | G28: 0.03 | H28: =Inputs!$B$32 -> 20 | I28: Y | J28: N | K28: CDR | L28: 0 | M28: Program End | N28: 0 | O28: =IFERROR(INDEX(Milestones!$E$5:$E$34,MATCH($K28,Milestones!$B$5:$B$34,0))+N($L28)*7,"") -> 46877 | P28: =IFERROR(INDEX(Milestones!$E$5:$E$34,MATCH($M28,Milestones!$B$5:$B$34,0))+N($N28)*7,"") -> 47483 | Q28: =IF(OR($O28="",$P28=""),"",MAX(0,($P28-$O28)/(365.25/12))) -> 19.909651 | R28: =IF(OR($A28="",$E28<>"Y"),0,IF($F28="SAR",$G28*Inputs!$B$9,IF($F28="LOE",$G28*N($Q28),$G28))*N($H28)*IF($I28="Y",Inputs!$B$16,1)*IF($J28="Y",Inputs!$B$22,1)) -> 480 | T28: =$R28*IF($S28<>"",$S28,Inputs!$B$11) -> 720 | U28: Per change (Inputs qty): hazard impact assessment and HTS update (304.2). ~3% of a SAR each. | V28: System Safety Engineer
A29: 401 | B29: 400 Verification | C29: Safety Verification (tests, demonstrations, induced/simulated failures) | D29: Safety verification report | E29: Y | F29: SAR | G29: 0.7 | H29: 1 | I29: Y | J29: Y | K29: CDR | L29: 0 | M29: Test Complete | N29: 0 | O29: =IFERROR(INDEX(Milestones!$E$5:$E$34,MATCH($K29,Milestones!$B$5:$B$34,0))+N($L29)*7,"") -> 46877 | P29: =IFERROR(INDEX(Milestones!$E$5:$E$34,MATCH($M29,Milestones!$B$5:$B$34,0))+N($N29)*7,"") -> 47334 | Q29: =IF(OR($O29="",$P29=""),"",MAX(0,($P29-$O29)/(365.25/12))) -> 15.014374 | R29: =IF(OR($A29="",$E29<>"Y"),0,IF($F29="SAR",$G29*Inputs!$B$9,IF($F29="LOE",$G29*N($Q29),$G29))*N($H29)*IF($I29="Y",Inputs!$B$16,1)*IF($J29="Y",Inputs!$B$22,1)) -> 728 | T29: =$R29*IF($S29<>"",$S29,Inputs!$B$11) -> 1092 | U29: Define and perform tests/demos/analyses on safety-significant HW, SW and procedures; induced or simulated failures (401.2). Fault-injection test planning, execution support and reporting. | V29: System Safety Engineer
A30: 402 | B30: 400 Verification | C30: Explosives Hazard Classification Data | D30: Hazard classification package | E30: N | F30: SAR | G30: 0.5 | H30: 1 | I30: Y | J30: N | K30: CDR | L30: 0 | M30: TRR | N30: 0 | O30: =IFERROR(INDEX(Milestones!$E$5:$E$34,MATCH($K30,Milestones!$B$5:$B$34,0))+N($L30)*7,"") -> 46877 | P30: =IFERROR(INDEX(Milestones!$E$5:$E$34,MATCH($M30,Milestones!$B$5:$B$34,0))+N($N30)*7,"") -> 47122 | Q30: =IF(OR($O30="",$P30=""),"",MAX(0,($P30-$O30)/(365.25/12))) -> 8.0492813 | R30: =IF(OR($A30="",$E30<>"Y"),0,IF($F30="SAR",$G30*Inputs!$B$9,IF($F30="LOE",$G30*N($Q30),$G30))*N($H30)*IF($I30="Y",Inputs!$B$16,1)*IF($J30="Y",Inputs!$B$22,1)) -> 0 | T30: =$R30*IF($S30<>"",$S30,Inputs!$B$11) -> 0 | U30: Not applicable to a battery program unless energetics are present. Default Not Tasked. | V30: System Safety Engineer
A31: 403 | B31: 400 Verification | C31: Explosive Ordnance Disposal Data | D31: EOD source data | E31: N | F31: SAR | G31: 0.3 | H31: 1 | I31: Y | J31: N | K31: CDR | L31: 0 | M31: TRR | N31: 0 | O31: =IFERROR(INDEX(Milestones!$E$5:$E$34,MATCH($K31,Milestones!$B$5:$B$34,0))+N($L31)*7,"") -> 46877 | P31: =IFERROR(INDEX(Milestones!$E$5:$E$34,MATCH($M31,Milestones!$B$5:$B$34,0))+N($N31)*7,"") -> 47122 | Q31: =IF(OR($O31="",$P31=""),"",MAX(0,($P31-$O31)/(365.25/12))) -> 8.0492813 | R31: =IF(OR($A31="",$E31<>"Y"),0,IF($F31="SAR",$G31*Inputs!$B$9,IF($F31="LOE",$G31*N($Q31),$G31))*N($H31)*IF($I31="Y",Inputs!$B$16,1)*IF($J31="Y",Inputs!$B$22,1)) -> 0 | T31: =$R31*IF($S31<>"",$S31,Inputs!$B$11) -> 0 | U31: Not applicable unless explosives are present. Default Not Tasked. | V31: System Safety Engineer
A32: SW-LOR | B32: 400 Verification | C32: Software Level-of-Rigor tasks (Section 4.4, Table V) | D32: LOR analysis & test evidence | E32: Y | F32: SAR | G32: 0.6 | H32: 1 | I32: Y | J32: Y | K32: PDR | L32: 0 | M32: TRR | N32: 0 | O32: =IFERROR(INDEX(Milestones!$E$5:$E$34,MATCH($K32,Milestones!$B$5:$B$34,0))+N($L32)*7,"") -> 46695 | P32: =IFERROR(INDEX(Milestones!$E$5:$E$34,MATCH($M32,Milestones!$B$5:$B$34,0))+N($N32)*7,"") -> 47122 | Q32: =IF(OR($O32="",$P32=""),"",MAX(0,($P32-$O32)/(365.25/12))) -> 14.028747 | R32: =IF(OR($A32="",$E32<>"Y"),0,IF($F32="SAR",$G32*Inputs!$B$9,IF($F32="LOE",$G32*N($Q32),$G32))*N($H32)*IF($I32="Y",Inputs!$B$16,1)*IF($J32="Y",Inputs!$B$22,1)) -> 624 | T32: =$R32*IF($S32<>"",$S32,Inputs!$B$11) -> 936 | U32: Not a numbered task but required by 4.4.1–4.4.3: requirements/architecture/design/code analysis and safety-specific testing per SwCI. Strongly scaled by the SwCI multiplier. | V32: Software Safety Engineer
A33: LOE-1 | B33: LOE / Other | C33: System Safety Working Group meetings | D33: Meeting prep, attendance, minutes, actions | E33: Y | F33: LOE | G33: 8 | H33: 1 | I33: Y | J33: N | K33: Program Start | L33: 0 | M33: Program End | N33: 0 | O33: =IFERROR(INDEX(Milestones!$E$5:$E$34,MATCH($K33,Milestones!$B$5:$B$34,0))+N($L33)*7,"") -> 46391 | P33: =IFERROR(INDEX(Milestones!$E$5:$E$34,MATCH($M33,Milestones!$B$5:$B$34,0))+N($N33)*7,"") -> 47483 | Q33: =IF(OR($O33="",$P33=""),"",MAX(0,($P33-$O33)/(365.25/12))) -> 35.876797 | R33: =IF(OR($A33="",$E33<>"Y"),0,IF($F33="SAR",$G33*Inputs!$B$9,IF($F33="LOE",$G33*N($Q33),$G33))*N($H33)*IF($I33="Y",Inputs!$B$16,1)*IF($J33="Y",Inputs!$B$22,1)) -> 287.01437 | T33: =$R33*IF($S33<>"",$S33,Inputs!$B$11) -> 430.52156 | U33: Assumes a monthly SSWG: 2 hrs meeting + prep/minutes/actions for the safety lead. Increase Qty for additional attendees. | V33: Safety Lead
A34: LOE-2 | B34: LOE / Other | C34: Design review safety data packages (SRR/PDR/CDR/TRR) | D34: Safety briefing packages | E34: Y | F34: SAR | G34: 0.1 | H34: =Inputs!$B$34 -> 4 | I34: Y | J34: N | K34: SRR | L34: -6 | M34: TRR | N34: 0 | O34: =IFERROR(INDEX(Milestones!$E$5:$E$34,MATCH($K34,Milestones!$B$5:$B$34,0))+N($L34)*7,"") -> 46439 | P34: =IFERROR(INDEX(Milestones!$E$5:$E$34,MATCH($M34,Milestones!$B$5:$B$34,0))+N($N34)*7,"") -> 47122 | Q34: =IF(OR($O34="",$P34=""),"",MAX(0,($P34-$O34)/(365.25/12))) -> 22.439425 | R34: =IF(OR($A34="",$E34<>"Y"),0,IF($F34="SAR",$G34*Inputs!$B$9,IF($F34="LOE",$G34*N($Q34),$G34))*N($H34)*IF($I34="Y",Inputs!$B$16,1)*IF($J34="Y",Inputs!$B$22,1)) -> 320 | T34: =$R34*IF($S34<>"",$S34,Inputs!$B$11) -> 480 | U34: Per design review (Inputs qty): hazard status briefing, risk matrix, open items. Distinct from Task 104 attendance. | V34: Safety Analyst
A35: LOE-3 | B35: LOE / Other | C35: Safety program management, BOE/EVM upkeep, travel | D35: Internal management | E35: Y | F35: LOE | G35: 6 | H35: 1 | I35: N | J35: N | K35: Program Start | L35: 0 | M35: Program End | N35: 0 | O35: =IFERROR(INDEX(Milestones!$E$5:$E$34,MATCH($K35,Milestones!$B$5:$B$34,0))+N($L35)*7,"") -> 46391 | P35: =IFERROR(INDEX(Milestones!$E$5:$E$34,MATCH($M35,Milestones!$B$5:$B$34,0))+N($N35)*7,"") -> 47483 | Q35: =IF(OR($O35="",$P35=""),"",MAX(0,($P35-$O35)/(365.25/12))) -> 35.876797 | R35: =IF(OR($A35="",$E35<>"Y"),0,IF($F35="SAR",$G35*Inputs!$B$9,IF($F35="LOE",$G35*N($Q35),$G35))*N($H35)*IF($I35="Y",Inputs!$B$16,1)*IF($J35="Y",Inputs!$B$22,1)) -> 215.26078 | T35: =$R35*IF($S35<>"",$S35,Inputs!$B$11) -> 322.89117 | U35: Internal overhead not tied to a task: EVM/BOE maintenance, scheduling, travel. Complexity not applied. | V35: Safety Lead
O36: =IFERROR(INDEX(Milestones!$E$5:$E$34,MATCH($K36,Milestones!$B$5:$B$34,0))+N($L36)*7,"") | P36: =IFERROR(INDEX(Milestones!$E$5:$E$34,MATCH($M36,Milestones!$B$5:$B$34,0))+N($N36)*7,"") | Q36: =IF(OR($O36="",$P36=""),"",MAX(0,($P36-$O36)/(365.25/12))) | R36: =IF(OR($A36="",$E36<>"Y"),0,IF($F36="SAR",$G36*Inputs!$B$9,IF($F36="LOE",$G36*N($Q36),$G36))*N($H36)*IF($I36="Y",Inputs!$B$16,1)*IF($J36="Y",Inputs!$B$22,1)) -> 0 | T36: =$R36*IF($S36<>"",$S36,Inputs!$B$11) -> 0
O37: =IFERROR(INDEX(Milestones!$E$5:$E$34,MATCH($K37,Milestones!$B$5:$B$34,0))+N($L37)*7,"") | P37: =IFERROR(INDEX(Milestones!$E$5:$E$34,MATCH($M37,Milestones!$B$5:$B$34,0))+N($N37)*7,"") | Q37: =IF(OR($O37="",$P37=""),"",MAX(0,($P37-$O37)/(365.25/12))) | R37: =IF(OR($A37="",$E37<>"Y"),0,IF($F37="SAR",$G37*Inputs!$B$9,IF($F37="LOE",$G37*N($Q37),$G37))*N($H37)*IF($I37="Y",Inputs!$B$16,1)*IF($J37="Y",Inputs!$B$22,1)) -> 0 | T37: =$R37*IF($S37<>"",$S37,Inputs!$B$11) -> 0
O38: =IFERROR(INDEX(Milestones!$E$5:$E$34,MATCH($K38,Milestones!$B$5:$B$34,0))+N($L38)*7,"") | P38: =IFERROR(INDEX(Milestones!$E$5:$E$34,MATCH($M38,Milestones!$B$5:$B$34,0))+N($N38)*7,"") | Q38: =IF(OR($O38="",$P38=""),"",MAX(0,($P38-$O38)/(365.25/12))) | R38: =IF(OR($A38="",$E38<>"Y"),0,IF($F38="SAR",$G38*Inputs!$B$9,IF($F38="LOE",$G38*N($Q38),$G38))*N($H38)*IF($I38="Y",Inputs!$B$16,1)*IF($J38="Y",Inputs!$B$22,1)) -> 0 | T38: =$R38*IF($S38<>"",$S38,Inputs!$B$11) -> 0
O39: =IFERROR(INDEX(Milestones!$E$5:$E$34,MATCH($K39,Milestones!$B$5:$B$34,0))+N($L39)*7,"") | P39: =IFERROR(INDEX(Milestones!$E$5:$E$34,MATCH($M39,Milestones!$B$5:$B$34,0))+N($N39)*7,"") | Q39: =IF(OR($O39="",$P39=""),"",MAX(0,($P39-$O39)/(365.25/12))) | R39: =IF(OR($A39="",$E39<>"Y"),0,IF($F39="SAR",$G39*Inputs!$B$9,IF($F39="LOE",$G39*N($Q39),$G39))*N($H39)*IF($I39="Y",Inputs!$B$16,1)*IF($J39="Y",Inputs!$B$22,1)) -> 0 | T39: =$R39*IF($S39<>"",$S39,Inputs!$B$11) -> 0
O40: =IFERROR(INDEX(Milestones!$E$5:$E$34,MATCH($K40,Milestones!$B$5:$B$34,0))+N($L40)*7,"") | P40: =IFERROR(INDEX(Milestones!$E$5:$E$34,MATCH($M40,Milestones!$B$5:$B$34,0))+N($N40)*7,"") | Q40: =IF(OR($O40="",$P40=""),"",MAX(0,($P40-$O40)/(365.25/12))) | R40: =IF(OR($A40="",$E40<>"Y"),0,IF($F40="SAR",$G40*Inputs!$B$9,IF($F40="LOE",$G40*N($Q40),$G40))*N($H40)*IF($I40="Y",Inputs!$B$16,1)*IF($J40="Y",Inputs!$B$22,1)) -> 0 | T40: =$R40*IF($S40<>"",$S40,Inputs!$B$11) -> 0
O41: =IFERROR(INDEX(Milestones!$E$5:$E$34,MATCH($K41,Milestones!$B$5:$B$34,0))+N($L41)*7,"") | P41: =IFERROR(INDEX(Milestones!$E$5:$E$34,MATCH($M41,Milestones!$B$5:$B$34,0))+N($N41)*7,"") | Q41: =IF(OR($O41="",$P41=""),"",MAX(0,($P41-$O41)/(365.25/12))) | R41: =IF(OR($A41="",$E41<>"Y"),0,IF($F41="SAR",$G41*Inputs!$B$9,IF($F41="LOE",$G41*N($Q41),$G41))*N($H41)*IF($I41="Y",Inputs!$B$16,1)*IF($J41="Y",Inputs!$B$22,1)) -> 0 | T41: =$R41*IF($S41<>"",$S41,Inputs!$B$11) -> 0
...

Sheet Phasing
A1: Monthly Phasing — hours spread evenly across each row's start–end window
A2: ="Basis: "&Inputs!$B$7&" | Hours per FTE-month: "&TEXT(Inputs!$B$6,"0") -> Basis: P50 | Hours per FTE-month: 156
E3: Month # | F3: =IF(F4="","",1) -> 1 | G3: =IF(G4="","",2) -> 2 | H3: =IF(H4="","",3) -> 3 | I3: =IF(I4="","",4) -> 4 | J3: =IF(J4="","",5) -> 5 | K3: =IF(K4="","",6) -> 6 | L3: =IF(L4="","",7) -> 7 | M3: =IF(M4="","",8) -> 8 | N3: =IF(N4="","",9) -> 9 | O3: =IF(O4="","",10) -> 10 | P3: =IF(P4="","",11) -> 11 | Q3: =IF(Q4="","",12) -> 12 | R3: =IF(R4="","",13) -> 13 | S3: =IF(S4="","",14) -> 14 | T3: =IF(T4="","",15) -> 15 | U3: =IF(U4="","",16) -> 16 | V3: =IF(V4="","",17) -> 17 | W3: =IF(W4="","",18) -> 18 | X3: =IF(X4="","",19) -> 19 | Y3: =IF(Y4="","",20) -> 20 | Z3: =IF(Z4="","",21) -> 21 | AA3: =IF(AA4="","",22) -> 22 | AB3: =IF(AB4="","",23) -> 23 | AC3: =IF(AC4="","",24) -> 24 | AD3: =IF(AD4="","",25) -> 25 | AE3: =IF(AE4="","",26) -> 26 | AF3: =IF(AF4="","",27) -> 27 | AG3: =IF(AG4="","",28) -> 28 | AH3: =IF(AH4="","",29) -> 29 | AI3: =IF(AI4="","",30) -> 30 | AJ3: =IF(AJ4="","",31) -> 31 | AK3: =IF(AK4="","",32) -> 32 | AL3: =IF(AL4="","",33) -> 33 | AM3: =IF(AM4="","",34) -> 34 | AN3: =IF(AN4="","",35) -> 35 | AO3: =IF(AO4="","",36) -> 36 | AP3: =IF(AP4="","",37) | AQ3: =IF(AQ4="","",38) | AR3: =IF(AR4="","",39) | AS3: =IF(AS4="","",40) | AT3: =IF(AT4="","",41) | AU3: =IF(AU4="","",42) | AV3: =IF(AV4="","",43) | AW3: =IF(AW4="","",44) | AX3: =IF(AX4="","",45) | AY3: =IF(AY4="","",46) | AZ3: =IF(AZ4="","",47) | BA3: =IF(BA4="","",48) | BB3: =IF(BB4="","",49) | BC3: =IF(BC4="","",50) | BD3: =IF(BD4="","",51) | BE3: =IF(BE4="","",52) | BF3: =IF(BF4="","",53) | BG3: =IF(BG4="","",54) | BH3: =IF(BH4="","",55) | BI3: =IF(BI4="","",56) | BJ3: =IF(BJ4="","",57) | BK3: =IF(BK4="","",58) | BL3: =IF(BL4="","",59) | BM3: =IF(BM4="","",60) | BN3: =IF(BN4="","",61) | BO3: =IF(BO4="","",62) | BP3: =IF(BP4="","",63) | BQ3: =IF(BQ4="","",64) | BR3: =IF(BR4="","",65) | BS3: =IF(BS4="","",66) | BT3: =IF(BT4="","",67) | BU3: =IF(BU4="","",68) | BV3: =IF(BV4="","",69) | BW3: =IF(BW4="","",70) | BX3: =IF(BX4="","",71) | BY3: =IF(BY4="","",72)
A4: Task | B4: Title | C4: Start | D4: End | E4: Hours | F4: =IF(EDATE(Inputs!$B$4,0)>Inputs!$B$5,"",EDATE(Inputs!$B$4,0)) -> 46391 | G4: =IF(EDATE(Inputs!$B$4,1)>Inputs!$B$5,"",EDATE(Inputs!$B$4,1)) -> 46422 | H4: =IF(EDATE(Inputs!$B$4,2)>Inputs!$B$5,"",EDATE(Inputs!$B$4,2)) -> 46450 | I4: =IF(EDATE(Inputs!$B$4,3)>Inputs!$B$5,"",EDATE(Inputs!$B$4,3)) -> 46481 | J4: =IF(EDATE(Inputs!$B$4,4)>Inputs!$B$5,"",EDATE(Inputs!$B$4,4)) -> 46511 | K4: =IF(EDATE(Inputs!$B$4,5)>Inputs!$B$5,"",EDATE(Inputs!$B$4,5)) -> 46542 | L4: =IF(EDATE(Inputs!$B$4,6)>Inputs!$B$5,"",EDATE(Inputs!$B$4,6)) -> 46572 | M4: =IF(EDATE(Inputs!$B$4,7)>Inputs!$B$5,"",EDATE(Inputs!$B$4,7)) -> 46603 | N4: =IF(EDATE(Inputs!$B$4,8)>Inputs!$B$5,"",EDATE(Inputs!$B$4,8)) -> 46634 | O4: =IF(EDATE(Inputs!$B$4,9)>Inputs!$B$5,"",EDATE(Inputs!$B$4,9)) -> 46664 | P4: =IF(EDATE(Inputs!$B$4,10)>Inputs!$B$5,"",EDATE(Inputs!$B$4,10)) -> 46695 | Q4: =IF(EDATE(Inputs!$B$4,11)>Inputs!$B$5,"",EDATE(Inputs!$B$4,11)) -> 46725 | R4: =IF(EDATE(Inputs!$B$4,12)>Inputs!$B$5,"",EDATE(Inputs!$B$4,12)) -> 46756 | S4: =IF(EDATE(Inputs!$B$4,13)>Inputs!$B$5,"",EDATE(Inputs!$B$4,13)) -> 46787 | T4: =IF(EDATE(Inputs!$B$4,14)>Inputs!$B$5,"",EDATE(Inputs!$B$4,14)) -> 46816 | U4: =IF(EDATE(Inputs!$B$4,15)>Inputs!$B$5,"",EDATE(Inputs!$B$4,15)) -> 46847 | V4: =IF(EDATE(Inputs!$B$4,16)>Inputs!$B$5,"",EDATE(Inputs!$B$4,16)) -> 46877 | W4: =IF(EDATE(Inputs!$B$4,17)>Inputs!$B$5,"",EDATE(Inputs!$B$4,17)) -> 46908 | X4: =IF(EDATE(Inputs!$B$4,18)>Inputs!$B$5,"",EDATE(Inputs!$B$4,18)) -> 46938 | Y4: =IF(EDATE(Inputs!$B$4,19)>Inputs!$B$5,"",EDATE(Inputs!$B$4,19)) -> 46969 | Z4: =IF(EDATE(Inputs!$B$4,20)>Inputs!$B$5,"",EDATE(Inputs!$B$4,20)) -> 47000 | AA4: =IF(EDATE(Inputs!$B$4,21)>Inputs!$B$5,"",EDATE(Inputs!$B$4,21)) -> 47030 | AB4: =IF(EDATE(Inputs!$B$4,22)>Inputs!$B$5,"",EDATE(Inputs!$B$4,22)) -> 47061 | AC4: =IF(EDATE(Inputs!$B$4,23)>Inputs!$B$5,"",EDATE(Inputs!$B$4,23)) -> 47091 | AD4: =IF(EDATE(Inputs!$B$4,24)>Inputs!$B$5,"",EDATE(Inputs!$B$4,24)) -> 47122 | AE4: =IF(EDATE(Inputs!$B$4,25)>Inputs!$B$5,"",EDATE(Inputs!$B$4,25)) -> 47153 | AF4: =IF(EDATE(Inputs!$B$4,26)>Inputs!$B$5,"",EDATE(Inputs!$B$4,26)) -> 47181 | AG4: =IF(EDATE(Inputs!$B$4,27)>Inputs!$B$5,"",EDATE(Inputs!$B$4,27)) -> 47212 | AH4: =IF(EDATE(Inputs!$B$4,28)>Inputs!$B$5,"",EDATE(Inputs!$B$4,28)) -> 47242 | AI4: =IF(EDATE(Inputs!$B$4,29)>Inputs!$B$5,"",EDATE(Inputs!$B$4,29)) -> 47273 | AJ4: =IF(EDATE(Inputs!$B$4,30)>Inputs!$B$5,"",EDATE(Inputs!$B$4,30)) -> 47303 | AK4: =IF(EDATE(Inputs!$B$4,31)>Inputs!$B$5,"",EDATE(Inputs!$B$4,31)) -> 47334 | AL4: =IF(EDATE(Inputs!$B$4,32)>Inputs!$B$5,"",EDATE(Inputs!$B$4,32)) -> 47365 | AM4: =IF(EDATE(Inputs!$B$4,33)>Inputs!$B$5,"",EDATE(Inputs!$B$4,33)) -> 47395 | AN4: =IF(EDATE(Inputs!$B$4,34)>Inputs!$B$5,"",EDATE(Inputs!$B$4,34)) -> 47426 | AO4: =IF(EDATE(Inputs!$B$4,35)>Inputs!$B$5,"",EDATE(Inputs!$B$4,35)) -> 47456 | AP4: =IF(EDATE(Inputs!$B$4,36)>Inputs!$B$5,"",EDATE(Inputs!$B$4,36)) | AQ4: =IF(EDATE(Inputs!$B$4,37)>Inputs!$B$5,"",EDATE(Inputs!$B$4,37)) | AR4: =IF(EDATE(Inputs!$B$4,38)>Inputs!$B$5,"",EDATE(Inputs!$B$4,38)) | AS4: =IF(EDATE(Inputs!$B$4,39)>Inputs!$B$5,"",EDATE(Inputs!$B$4,39)) | AT4: =IF(EDATE(Inputs!$B$4,40)>Inputs!$B$5,"",EDATE(Inputs!$B$4,40)) | AU4: =IF(EDATE(Inputs!$B$4,41)>Inputs!$B$5,"",EDATE(Inputs!$B$4,41)) | AV4: =IF(EDATE(Inputs!$B$4,42)>Inputs!$B$5,"",EDATE(Inputs!$B$4,42)) | AW4: =IF(EDATE(Inputs!$B$4,43)>Inputs!$B$5,"",EDATE(Inputs!$B$4,43)) | AX4: =IF(EDATE(Inputs!$B$4,44)>Inputs!$B$5,"",EDATE(Inputs!$B$4,44)) | AY4: =IF(EDATE(Inputs!$B$4,45)>Inputs!$B$5,"",EDATE(Inputs!$B$4,45)) | AZ4: =IF(EDATE(Inputs!$B$4,46)>Inputs!$B$5,"",EDATE(Inputs!$B$4,46)) | BA4: =IF(EDATE(Inputs!$B$4,47)>Inputs!$B$5,"",EDATE(Inputs!$B$4,47)) | BB4: =IF(EDATE(Inputs!$B$4,48)>Inputs!$B$5,"",EDATE(Inputs!$B$4,48)) | BC4: =IF(EDATE(Inputs!$B$4,49)>Inputs!$B$5,"",EDATE(Inputs!$B$4,49)) | BD4: =IF(EDATE(Inputs!$B$4,50)>Inputs!$B$5,"",EDATE(Inputs!$B$4,50)) | BE4: =IF(EDATE(Inputs!$B$4,51)>Inputs!$B$5,"",EDATE(Inputs!$B$4,51)) | BF4: =IF(EDATE(Inputs!$B$4,52)>Inputs!$B$5,"",EDATE(Inputs!$B$4,52)) | BG4: =IF(EDATE(Inputs!$B$4,53)>Inputs!$B$5,"",EDATE(Inputs!$B$4,53)) | BH4: =IF(EDATE(Inputs!$B$4,54)>Inputs!$B$5,"",EDATE(Inputs!$B$4,54)) | BI4: =IF(EDATE(Inputs!$B$4,55)>Inputs!$B$5,"",EDATE(Inputs!$B$4,55)) | BJ4: =IF(EDATE(Inputs!$B$4,56)>Inputs!$B$5,"",EDATE(Inputs!$B$4,56)) | BK4: =IF(EDATE(Inputs!$B$4,57)>Inputs!$B$5,"",EDATE(Inputs!$B$4,57)) | BL4: =IF(EDATE(Inputs!$B$4,58)>Inputs!$B$5,"",EDATE(Inputs!$B$4,58)) | BM4: =IF(EDATE(Inputs!$B$4,59)>Inputs!$B$5,"",EDATE(Inputs!$B$4,59)) | BN4: =IF(EDATE(Inputs!$B$4,60)>Inputs!$B$5,"",EDATE(Inputs!$B$4,60)) | BO4: =IF(EDATE(Inputs!$B$4,61)>Inputs!$B$5,"",EDATE(Inputs!$B$4,61)) | BP4: =IF(EDATE(Inputs!$B$4,62)>Inputs!$B$5,"",EDATE(Inputs!$B$4,62)) | BQ4: =IF(EDATE(Inputs!$B$4,63)>Inputs!$B$5,"",EDATE(Inputs!$B$4,63)) | BR4: =IF(EDATE(Inputs!$B$4,64)>Inputs!$B$5,"",EDATE(Inputs!$B$4,64)) | BS4: =IF(EDATE(Inputs!$B$4,65)>Inputs!$B$5,"",EDATE(Inputs!$B$4,65)) | BT4: =IF(EDATE(Inputs!$B$4,66)>Inputs!$B$5,"",EDATE(Inputs!$B$4,66)) | BU4: =IF(EDATE(Inputs!$B$4,67)>Inputs!$B$5,"",EDATE(Inputs!$B$4,67)) | BV4: =IF(EDATE(Inputs!$B$4,68)>Inputs!$B$5,"",EDATE(Inputs!$B$4,68)) | BW4: =IF(EDATE(Inputs!$B$4,69)>Inputs!$B$5,"",EDATE(Inputs!$B$4,69)) | BX4: =IF(EDATE(Inputs!$B$4,70)>Inputs!$B$5,"",EDATE(Inputs!$B$4,70)) | BY4: =IF(EDATE(Inputs!$B$4,71)>Inputs!$B$5,"",EDATE(Inputs!$B$4,71))
A5: =IF(BOE!$A6="","",BOE!$A6) -> 101 | B5: =IF(BOE!$A6="","",BOE!$C6) -> Hazard identification & mitigation effort using the system safety methodology (program execution) | C5: =IF(BOE!$O6="","",BOE!$O6) -> 46391 | D5: =IF(BOE!$P6="","",BOE!$P6) -> 47483 | E5: =IF(Inputs!$B$7="P90",BOE!$T6,BOE!$R6) -> 717.53593 | F5: =IF(OR(F$4="",$C5="",$D5="",N($E5)=0),"",$E5*MAX(0,MIN($D5+1,EDATE(F$4,1))-MAX($C5,F$4))/MAX(1,$D5+1-$C5)) -> 20.350973 | G5: =IF(OR(G$4="",$C5="",$D5="",N($E5)=0),"",$E5*MAX(0,MIN($D5+1,EDATE(G$4,1))-MAX($C5,G$4))/MAX(1,$D5+1-$C5)) -> 18.381524 | H5: =IF(OR(H$4="",$C5="",$D5="",N($E5)=0),"",$E5*MAX(0,MIN($D5+1,EDATE(H$4,1))-MAX($C5,H$4))/MAX(1,$D5+1-$C5)) -> 20.350973 | I5: =IF(OR(I$4="",$C5="",$D5="",N($E5)=0),"",$E5*MAX(0,MIN($D5+1,EDATE(I$4,1))-MAX($C5,I$4))/MAX(1,$D5+1-$C5)) -> 19.69449 | J5: =IF(OR(J$4="",$C5="",$D5="",N($E5)=0),"",$E5*MAX(0,MIN($D5+1,EDATE(J$4,1))-MAX($C5,J$4))/MAX(1,$D5+1-$C5)) -> 20.350973 | K5: =IF(OR(K$4="",$C5="",$D5="",N($E5)=0),"",$E5*MAX(0,MIN($D5+1,EDATE(K$4,1))-MAX($C5,K$4))/MAX(1,$D5+1-$C5)) -> 19.69449 | L5: =IF(OR(L$4="",$C5="",$D5="",N($E5)=0),"",$E5*MAX(0,MIN($D5+1,EDATE(L$4,1))-MAX($C5,L$4))/MAX(1,$D5+1-$C5)) -> 20.350973 | M5: =IF(OR(M$4="",$C5="",$D5="",N($E5)=0),"",$E5*MAX(0,MIN($D5+1,EDATE(M$4,1))-MAX($C5,M$4))/MAX(1,$D5+1-$C5)) -> 20.350973 | ... BY5: =IF(OR(BY$4="",$C5="",$D5="",N($E5)=0),"",$E5*MAX(0,MIN($D5+1,EDATE(BY$4,1))-MAX($C5,BY$4))/MAX(1,$D5+1-$C5))
A6: =IF(BOE!$A7="","",BOE!$A7) -> 102 | B6: =IF(BOE!$A7="","",BOE!$C7) -> System Safety Program Plan (SSPP) | C6: =IF(BOE!$O7="","",BOE!$O7) -> 46391 | D6: =IF(BOE!$P7="","",BOE!$P7) -> 46481 | E6: =IF(Inputs!$B$7="P90",BOE!$T7,BOE!$R7) -> 320 | F6: =IF(OR(F$4="",$C6="",$D6="",N($E6)=0),"",$E6*MAX(0,MIN($D6+1,EDATE(F$4,1))-MAX($C6,F$4))/MAX(1,$D6+1-$C6)) -> 109.01099 | G6: =IF(OR(G$4="",$C6="",$D6="",N($E6)=0),"",$E6*MAX(0,MIN($D6+1,EDATE(G$4,1))-MAX($C6,G$4))/MAX(1,$D6+1-$C6)) -> 98.461538 | H6: =IF(OR(H$4="",$C6="",$D6="",N($E6)=0),"",$E6*MAX(0,MIN($D6+1,EDATE(H$4,1))-MAX($C6,H$4))/MAX(1,$D6+1-$C6)) -> 109.01099 | I6: =IF(OR(I$4="",$C6="",$D6="",N($E6)=0),"",$E6*MAX(0,MIN($D6+1,EDATE(I$4,1))-MAX($C6,I$4))/MAX(1,$D6+1-$C6)) -> 3.5164835 | J6: =IF(OR(J$4="",$C6="",$D6="",N($E6)=0),"",$E6*MAX(0,MIN($D6+1,EDATE(J$4,1))-MAX($C6,J$4))/MAX(1,$D6+1-$C6)) -> 0 | K6: =IF(OR(K$4="",$C6="",$D6="",N($E6)=0),"",$E6*MAX(0,MIN($D6+1,EDATE(K$4,1))-MAX($C6,K$4))/MAX(1,$D6+1-$C6)) -> 0 | L6: =IF(OR(L$4="",$C6="",$D6="",N($E6)=0),"",$E6*MAX(0,MIN($D6+1,EDATE(L$4,1))-MAX($C6,L$4))/MAX(1,$D6+1-$C6)) -> 0 | M6: =IF(OR(M$4="",$C6="",$D6="",N($E6)=0),"",$E6*MAX(0,MIN($D6+1,EDATE(M$4,1))-MAX($C6,M$4))/MAX(1,$D6+1-$C6)) -> 0 | ... BY6: =IF(OR(BY$4="",$C6="",$D6="",N($E6)=0),"",$E6*MAX(0,MIN($D6+1,EDATE(BY$4,1))-MAX($C6,BY$4))/MAX(1,$D6+1-$C6))
A7: =IF(BOE!$A8="","",BOE!$A8) -> 103 | B7: =IF(BOE!$A8="","",BOE!$C8) -> Hazard Management Plan (HMP) — other functional disciplines | C7: =IF(BOE!$O8="","",BOE!$O8) -> 46391 | D7: =IF(BOE!$P8="","",BOE!$P8) -> 46481 | E7: =IF(Inputs!$B$7="P90",BOE!$T8,BOE!$R8) -> 0 | F7: =IF(OR(F$4="",$C7="",$D7="",N($E7)=0),"",$E7*MAX(0,MIN($D7+1,EDATE(F$4,1))-MAX($C7,F$4))/MAX(1,$D7+1-$C7)) | G7: =IF(OR(G$4="",$C7="",$D7="",N($E7)=0),"",$E7*MAX(0,MIN($D7+1,EDATE(G$4,1))-MAX($C7,G$4))/MAX(1,$D7+1-$C7)) | H7: =IF(OR(H$4="",$C7="",$D7="",N($E7)=0),"",$E7*MAX(0,MIN($D7+1,EDATE(H$4,1))-MAX($C7,H$4))/MAX(1,$D7+1-$C7)) | I7: =IF(OR(I$4="",$C7="",$D7="",N($E7)=0),"",$E7*MAX(0,MIN($D7+1,EDATE(I$4,1))-MAX($C7,I$4))/MAX(1,$D7+1-$C7)) | J7: =IF(OR(J$4="",$C7="",$D7="",N($E7)=0),"",$E7*MAX(0,MIN($D7+1,EDATE(J$4,1))-MAX($C7,J$4))/MAX(1,$D7+1-$C7)) | K7: =IF(OR(K$4="",$C7="",$D7="",N($E7)=0),"",$E7*MAX(0,MIN($D7+1,EDATE(K$4,1))-MAX($C7,K$4))/MAX(1,$D7+1-$C7)) | L7: =IF(OR(L$4="",$C7="",$D7="",N($E7)=0),"",$E7*MAX(0,MIN($D7+1,EDATE(L$4,1))-MAX($C7,L$4))/MAX(1,$D7+1-$C7)) | M7: =IF(OR(M$4="",$C7="",$D7="",N($E7)=0),"",$E7*MAX(0,MIN($D7+1,EDATE(M$4,1))-MAX($C7,M$4))/MAX(1,$D7+1-$C7)) | ... BY7: =IF(OR(BY$4="",$C7="",$D7="",N($E7)=0),"",$E7*MAX(0,MIN($D7+1,EDATE(BY$4,1))-MAX($C7,BY$4))/MAX(1,$D7+1-$C7))
A8: =IF(BOE!$A9="","",BOE!$A9) -> 104 | B8: =IF(BOE!$A9="","",BOE!$C9) -> Support of Government reviews / audits / boards | C8: =IF(BOE!$O9="","",BOE!$O9) -> 46453 | D8: =IF(BOE!$P9="","",BOE!$P9) -> 47483 | E8: =IF(Inputs!$B$7="P90",BOE!$T9,BOE!$R9) -> 240 | F8: =IF(OR(F$4="",$C8="",$D8="",N($E8)=0),"",$E8*MAX(0,MIN($D8+1,EDATE(F$4,1))-MAX($C8,F$4))/MAX(1,$D8+1-$C8)) -> 0 | G8: =IF(OR(G$4="",$C8="",$D8="",N($E8)=0),"",$E8*MAX(0,MIN($D8+1,EDATE(G$4,1))-MAX($C8,G$4))/MAX(1,$D8+1-$C8)) -> 0 | H8: =IF(OR(H$4="",$C8="",$D8="",N($E8)=0),"",$E8*MAX(0,MIN($D8+1,EDATE(H$4,1))-MAX($C8,H$4))/MAX(1,$D8+1-$C8)) -> 6.5179437 | I8: =IF(OR(I$4="",$C8="",$D8="",N($E8)=0),"",$E8*MAX(0,MIN($D8+1,EDATE(I$4,1))-MAX($C8,I$4))/MAX(1,$D8+1-$C8)) -> 6.9835112 | J8: =IF(OR(J$4="",$C8="",$D8="",N($E8)=0),"",$E8*MAX(0,MIN($D8+1,EDATE(J$4,1))-MAX($C8,J$4))/MAX(1,$D8+1-$C8)) -> 7.2162949 | K8: =IF(OR(K$4="",$C8="",$D8="",N($E8)=0),"",$E8*MAX(0,MIN($D8+1,EDATE(K$4,1))-MAX($C8,K$4))/MAX(1,$D8+1-$C8)) -> 6.9835112 | L8: =IF(OR(L$4="",$C8="",$D8="",N($E8)=0),"",$E8*MAX(0,MIN($D8+1,EDATE(L$4,1))-MAX($C8,L$4))/MAX(1,$D8+1-$C8)) -> 7.2162949 | M8: =IF(OR(M$4="",$C8="",$D8="",N($E8)=0),"",$E8*MAX(0,MIN($D8+1,EDATE(M$4,1))-MAX($C8,M$4))/MAX(1,$D8+1-$C8)) -> 7.2162949 | ... BY8: =IF(OR(BY$4="",$C8="",$D8="",N($E8)=0),"",$E8*MAX(0,MIN($D8+1,EDATE(BY$4,1))-MAX($C8,BY$4))/MAX(1,$D8+1-$C8))
A9: =IF(BOE!$A10="","",BOE!$A10) -> 105 | B9: =IF(BOE!$A10="","",BOE!$C10) -> Integrated Product Team / Working Group support | C9: =IF(BOE!$O10="","",BOE!$O10) -> 46391 | D9: =IF(BOE!$P10="","",BOE!$P10) -> 47483 | E9: =IF(Inputs!$B$7="P90",BOE!$T10,BOE!$R10) -> 430.52156 | F9: =IF(OR(F$4="",$C9="",$D9="",N($E9)=0),"",$E9*MAX(0,MIN($D9+1,EDATE(F$4,1))-MAX($C9,F$4))/MAX(1,$D9+1-$C9)) -> 12.210584 | G9: =IF(OR(G$4="",$C9="",$D9="",N($E9)=0),"",$E9*MAX(0,MIN($D9+1,EDATE(G$4,1))-MAX($C9,G$4))/MAX(1,$D9+1-$C9)) -> 11.028915 | H9: =IF(OR(H$4="",$C9="",$D9="",N($E9)=0),"",$E9*MAX(0,MIN($D9+1,EDATE(H$4,1))-MAX($C9,H$4))/MAX(1,$D9+1-$C9)) -> 12.210584 | I9: =IF(OR(I$4="",$C9="",$D9="",N($E9)=0),"",$E9*MAX(0,MIN($D9+1,EDATE(I$4,1))-MAX($C9,I$4))/MAX(1,$D9+1-$C9)) -> 11.816694 | J9: =IF(OR(J$4="",$C9="",$D9="",N($E9)=0),"",$E9*MAX(0,MIN($D9+1,EDATE(J$4,1))-MAX($C9,J$4))/MAX(1,$D9+1-$C9)) -> 12.210584 | K9: =IF(OR(K$4="",$C9="",$D9="",N($E9)=0),"",$E9*MAX(0,MIN($D9+1,EDATE(K$4,1))-MAX($C9,K$4))/MAX(1,$D9+1-$C9)) -> 11.816694 | L9: =IF(OR(L$4="",$C9="",$D9="",N($E9)=0),"",$E9*MAX(0,MIN($D9+1,EDATE(L$4,1))-MAX($C9,L$4))/MAX(1,$D9+1-$C9)) -> 12.210584 | M9: =IF(OR(M$4="",$C9="",$D9="",N($E9)=0),"",$E9*MAX(0,MIN($D9+1,EDATE(M$4,1))-MAX($C9,M$4))/MAX(1,$D9+1-$C9)) -> 12.210584 | ... BY9: =IF(OR(BY$4="",$C9="",$D9="",N($E9)=0),"",$E9*MAX(0,MIN($D9+1,EDATE(BY$4,1))-MAX($C9,BY$4))/MAX(1,$D9+1-$C9))
A10: =IF(BOE!$A11="","",BOE!$A11) -> 106a | B10: =IF(BOE!$A11="","",BOE!$C11) -> Hazard Tracking System — establish | C10: =IF(BOE!$O11="","",BOE!$O11) -> 46391 | D10: =IF(BOE!$P11="","",BOE!$P11) -> 46481 | E10: =IF(Inputs!$B$7="P90",BOE!$T11,BOE!$R11) -> 120 | F10: =IF(OR(F$4="",$C10="",$D10="",N($E10)=0),"",$E10*MAX(0,MIN($D10+1,EDATE(F$4,1))-MAX($C10,F$4))/MAX(1,$D10+1-$C10)) -> 40.879121 | G10: =IF(OR(G$4="",$C10="",$D10="",N($E10)=0),"",$E10*MAX(0,MIN($D10+1,EDATE(G$4,1))-MAX($C10,G$4))/MAX(1,$D10+1-$C10)) -> 36.923077 | H10: =IF(OR(H$4="",$C10="",$D10="",N($E10)=0),"",$E10*MAX(0,MIN($D10+1,EDATE(H$4,1))-MAX($C10,H$4))/MAX(1,$D10+1-$C10)) -> 40.879121 | I10: =IF(OR(I$4="",$C10="",$D10="",N($E10)=0),"",$E10*MAX(0,MIN($D10+1,EDATE(I$4,1))-MAX($C10,I$4))/MAX(1,$D10+1-$C10)) -> 1.3186813 | J10: =IF(OR(J$4="",$C10="",$D10="",N($E10)=0),"",$E10*MAX(0,MIN($D10+1,EDATE(J$4,1))-MAX($C10,J$4))/MAX(1,$D10+1-$C10)) -> 0 | K10: =IF(OR(K$4="",$C10="",$D10="",N($E10)=0),"",$E10*MAX(0,MIN($D10+1,EDATE(K$4,1))-MAX($C10,K$4))/MAX(1,$D10+1-$C10)) -> 0 | L10: =IF(OR(L$4="",$C10="",$D10="",N($E10)=0),"",$E10*MAX(0,MIN($D10+1,EDATE(L$4,1))-MAX($C10,L$4))/MAX(1,$D10+1-$C10)) -> 0 | M10: =IF(OR(M$4="",$C10="",$D10="",N($E10)=0),"",$E10*MAX(0,MIN($D10+1,EDATE(M$4,1))-MAX($C10,M$4))/MAX(1,$D10+1-$C10)) -> 0 | ... BY10: =IF(OR(BY$4="",$C10="",$D10="",N($E10)=0),"",$E10*MAX(0,MIN($D10+1,EDATE(BY$4,1))-MAX($C10,BY$4))/MAX(1,$D10+1-$C10))
A11: =IF(BOE!$A12="","",BOE!$A12) -> 106b | B11: =IF(BOE!$A12="","",BOE!$C12) -> Hazard Tracking System — maintain | C11: =IF(BOE!$O12="","",BOE!$O12) -> 46481 | D11: =IF(BOE!$P12="","",BOE!$P12) -> 47483 | E11: =IF(Inputs!$B$7="P90",BOE!$T12,BOE!$R12) -> 263.35934 | F11: =IF(OR(F$4="",$C11="",$D11="",N($E11)=0),"",$E11*MAX(0,MIN($D11+1,EDATE(F$4,1))-MAX($C11,F$4))/MAX(1,$D11+1-$C11)) -> 0 | G11: =IF(OR(G$4="",$C11="",$D11="",N($E11)=0),"",$E11*MAX(0,MIN($D11+1,EDATE(G$4,1))-MAX($C11,G$4))/MAX(1,$D11+1-$C11)) -> 0 | H11: =IF(OR(H$4="",$C11="",$D11="",N($E11)=0),"",$E11*MAX(0,MIN($D11+1,EDATE(H$4,1))-MAX($C11,H$4))/MAX(1,$D11+1-$C11)) -> 0 | I11: =IF(OR(I$4="",$C11="",$D11="",N($E11)=0),"",$E11*MAX(0,MIN($D11+1,EDATE(I$4,1))-MAX($C11,I$4))/MAX(1,$D11+1-$C11)) -> 7.8771488 | J11: =IF(OR(J$4="",$C11="",$D11="",N($E11)=0),"",$E11*MAX(0,MIN($D11+1,EDATE(J$4,1))-MAX($C11,J$4))/MAX(1,$D11+1-$C11)) -> 8.1397205 | K11: =IF(OR(K$4="",$C11="",$D11="",N($E11)=0),"",$E11*MAX(0,MIN($D11+1,EDATE(K$4,1))-MAX($C11,K$4))/MAX(1,$D11+1-$C11)) -> 7.8771488 | L11: =IF(OR(L$4="",$C11="",$D11="",N($E11)=0),"",$E11*MAX(0,MIN($D11+1,EDATE(L$4,1))-MAX($C11,L$4))/MAX(1,$D11+1-$C11)) -> 8.1397205 | M11: =IF(OR(M$4="",$C11="",$D11="",N($E11)=0),"",$E11*MAX(0,MIN($D11+1,EDATE(M$4,1))-MAX($C11,M$4))/MAX(1,$D11+1-$C11)) -> 8.1397205 | ... BY11: =IF(OR(BY$4="",$C11="",$D11="",N($E11)=0),"",$E11*MAX(0,MIN($D11+1,EDATE(BY$4,1))-MAX($C11,BY$4))/MAX(1,$D11+1-$C11))
